package Hardmode.WorldGen;

import java.util.Random;

import Hardmode.Blocks.ModBlocks;
import net.minecraft.world.World;
import net.minecraft.world.gen.feature.WorldGenerator;

public class WorldGenEnderForgeDungeon extends WorldGenerator
{
	public WorldGenEnderForgeDungeon() 
	{ 
		
	}

	public boolean generate(World world, Random rand, int i, int j, int k)
    {
		world.setBlock(i + 0, j + 0, k + 0, ModBlocks.ShadowStone.blockID);
		world.setBlock(i + 0, j + 0, k + 1, ModBlocks.ShadowStone.blockID);
		world.setBlock(i + 0, j + 0, k + 2, ModBlocks.ShadowStone.blockID);
		world.setBlock(i + 0, j + 0, k + 3, ModBlocks.ShadowStone.blockID);
		world.setBlock(i + 0, j + 0, k + 4, ModBlocks.ShadowStone.blockID);
		world.setBlock(i + 0, j + 0, k + 5, ModBlocks.ShadowStone.blockID);
		world.setBlock(i + 0, j + 0, k + 6, ModBlocks.ShadowStone.blockID);
		world.setBlock(i + 0, j + 1, k + 0, ModBlocks.ShadowStone.blockID);
		world.setBlock(i + 0, j + 1, k + 1, ModBlocks.ShadowStone.blockID);
		world.setBlock(i + 0, j + 1, k + 2, ModBlocks.ShadowStone.blockID);
		world.setBlock(i + 0, j + 1, k + 3, ModBlocks.ShadowStone.blockID);
		world.setBlock(i + 0, j + 1, k + 4, ModBlocks.ShadowStone.blockID);
		world.setBlock(i + 0, j + 1, k + 5, ModBlocks.ShadowStone.blockID);
		world.setBlock(i + 0, j + 1, k + 6, ModBlocks.ShadowStone.blockID);
		world.setBlock(i + 0, j + 2, k + 0, ModBlocks.ShadowStone.blockID);
		world.setBlock(i + 0, j + 2, k + 1, ModBlocks.ShadowStone.blockID);
		world.setBlock(i + 0, j + 2, k + 2, ModBlocks.ShadowStone.blockID);
		world.setBlock(i + 0, j + 2, k + 3, ModBlocks.ShadowStone.blockID);
		world.setBlock(i + 0, j + 2, k + 4, ModBlocks.ShadowStone.blockID);
		world.setBlock(i + 0, j + 2, k + 5, ModBlocks.ShadowStone.blockID);
		world.setBlock(i + 0, j + 2, k + 6, ModBlocks.ShadowStone.blockID);
		world.setBlock(i + 0, j + 3, k + 0, ModBlocks.ShadowStone.blockID);
		world.setBlock(i + 0, j + 3, k + 1, ModBlocks.ShadowStone.blockID);
		world.setBlock(i + 0, j + 3, k + 2, ModBlocks.ShadowStone.blockID);
		world.setBlock(i + 0, j + 3, k + 3, ModBlocks.ShadowStone.blockID);
		world.setBlock(i + 0, j + 3, k + 4, ModBlocks.ShadowStone.blockID);
		world.setBlock(i + 0, j + 3, k + 5, ModBlocks.ShadowStone.blockID);
		world.setBlock(i + 0, j + 3, k + 6, ModBlocks.ShadowStone.blockID);
		world.setBlock(i + 0, j + 4, k + 0, ModBlocks.ShadowStone.blockID);
		world.setBlock(i + 0, j + 4, k + 1, ModBlocks.ShadowStone.blockID);
		world.setBlock(i + 0, j + 4, k + 2, ModBlocks.ShadowStone.blockID);
		world.setBlock(i + 0, j + 4, k + 3, ModBlocks.ShadowStone.blockID);
		world.setBlock(i + 0, j + 4, k + 4, ModBlocks.ShadowStone.blockID);
		world.setBlock(i + 0, j + 4, k + 5, ModBlocks.ShadowStone.blockID);
		world.setBlock(i + 0, j + 4, k + 6, ModBlocks.ShadowStone.blockID);
		world.setBlock(i + 1, j + 0, k + 0, ModBlocks.ShadowStone.blockID);
		world.setBlock(i + 1, j + 0, k + 1, ModBlocks.ShadowStone.blockID);
		world.setBlock(i + 1, j + 0, k + 2, ModBlocks.ShadowStone.blockID);
		world.setBlock(i + 1, j + 0, k + 3, ModBlocks.ShadowStone.blockID);
		world.setBlock(i + 1, j + 0, k + 4, ModBlocks.ShadowStone.blockID);
		world.setBlock(i + 1, j + 0, k + 5, ModBlocks.ShadowStone.blockID);
		world.setBlock(i + 1, j + 0, k + 6, ModBlocks.ShadowStone.blockID);
		world.setBlock(i + 1, j + 1, k + 0, ModBlocks.ShadowStone.blockID);
		world.setBlock(i + 1, j + 1, k + 1, 0);
		world.setBlock(i + 1, j + 1, k + 2, 0);
		world.setBlock(i + 1, j + 1, k + 3, 0);
		world.setBlock(i + 1, j + 1, k + 4, 0);
		world.setBlock(i + 1, j + 1, k + 5, 0);
		world.setBlock(i + 1, j + 1, k + 6, ModBlocks.ShadowStone.blockID);
		world.setBlock(i + 1, j + 2, k + 0, ModBlocks.ShadowStone.blockID);
		world.setBlock(i + 1, j + 2, k + 1, 0);
		world.setBlock(i + 1, j + 2, k + 2, 0);
		world.setBlock(i + 1, j + 2, k + 3, 0);
		world.setBlock(i + 1, j + 2, k + 4, 0);
		world.setBlock(i + 1, j + 2, k + 5, 0);
		world.setBlock(i + 1, j + 2, k + 6, ModBlocks.ShadowStone.blockID);
		world.setBlock(i + 1, j + 3, k + 0, ModBlocks.ShadowStone.blockID);
		world.setBlock(i + 1, j + 3, k + 1, 0);
		world.setBlock(i + 1, j + 3, k + 2, 0);
		world.setBlock(i + 1, j + 3, k + 3, 0);
		world.setBlock(i + 1, j + 3, k + 4, 0);
		world.setBlock(i + 1, j + 3, k + 5, 0);
		world.setBlock(i + 1, j + 3, k + 6, ModBlocks.ShadowStone.blockID);
		world.setBlock(i + 1, j + 4, k + 0, ModBlocks.ShadowStone.blockID);
		world.setBlock(i + 1, j + 4, k + 1, ModBlocks.ShadowStone.blockID);
		world.setBlock(i + 1, j + 4, k + 2, ModBlocks.ShadowStone.blockID);
		world.setBlock(i + 1, j + 4, k + 3, ModBlocks.ShadowStone.blockID);
		world.setBlock(i + 1, j + 4, k + 4, ModBlocks.ShadowStone.blockID);
		world.setBlock(i + 1, j + 4, k + 5, ModBlocks.ShadowStone.blockID);
		world.setBlock(i + 1, j + 4, k + 6, ModBlocks.ShadowStone.blockID);
		world.setBlock(i + 2, j + 0, k + 0, ModBlocks.ShadowStone.blockID);
		world.setBlock(i + 2, j + 0, k + 1, ModBlocks.ShadowStone.blockID);
		world.setBlock(i + 2, j + 0, k + 2, ModBlocks.ShadowStone.blockID);
		world.setBlock(i + 2, j + 0, k + 3, ModBlocks.ShadowStone.blockID);
		world.setBlock(i + 2, j + 0, k + 4, ModBlocks.ShadowStone.blockID);
		world.setBlock(i + 2, j + 0, k + 5, ModBlocks.ShadowStone.blockID);
		world.setBlock(i + 2, j + 0, k + 6, ModBlocks.ShadowStone.blockID);
		world.setBlock(i + 2, j + 1, k + 0, ModBlocks.ShadowStone.blockID);
		world.setBlock(i + 2, j + 1, k + 1, 0);
		world.setBlock(i + 2, j + 1, k + 2, 0);
		world.setBlock(i + 2, j + 1, k + 3, 0);
		world.setBlock(i + 2, j + 1, k + 4, 0);
		world.setBlock(i + 2, j + 1, k + 5, 0);
		world.setBlock(i + 2, j + 1, k + 6, ModBlocks.ShadowStone.blockID);
		world.setBlock(i + 2, j + 2, k + 0, ModBlocks.ShadowStone.blockID);
		world.setBlock(i + 2, j + 2, k + 1, 0);
		world.setBlock(i + 2, j + 2, k + 2, 0);
		world.setBlock(i + 2, j + 2, k + 3, 0);
		world.setBlock(i + 2, j + 2, k + 4, 0);
		world.setBlock(i + 2, j + 2, k + 5, 0);
		world.setBlock(i + 2, j + 2, k + 6, ModBlocks.ShadowStone.blockID);
		world.setBlock(i + 2, j + 3, k + 0, ModBlocks.ShadowStone.blockID);
		world.setBlock(i + 2, j + 3, k + 1, 0);
		world.setBlock(i + 2, j + 3, k + 2, 0);
		world.setBlock(i + 2, j + 3, k + 3, 0);
		world.setBlock(i + 2, j + 3, k + 4, 0);
		world.setBlock(i + 2, j + 3, k + 5, 0);
		world.setBlock(i + 2, j + 3, k + 6, ModBlocks.ShadowStone.blockID);
		world.setBlock(i + 2, j + 4, k + 0, ModBlocks.ShadowStone.blockID);
		world.setBlock(i + 2, j + 4, k + 1, ModBlocks.ShadowStone.blockID);
		world.setBlock(i + 2, j + 4, k + 2, ModBlocks.ShadowStone.blockID);
		world.setBlock(i + 2, j + 4, k + 3, ModBlocks.ShadowStone.blockID);
		world.setBlock(i + 2, j + 4, k + 4, ModBlocks.ShadowStone.blockID);
		world.setBlock(i + 2, j + 4, k + 5, ModBlocks.ShadowStone.blockID);
		world.setBlock(i + 2, j + 4, k + 6, ModBlocks.ShadowStone.blockID);
		world.setBlock(i + 3, j + 0, k + 0, ModBlocks.ShadowStone.blockID);
		world.setBlock(i + 3, j + 0, k + 1, ModBlocks.ShadowStone.blockID);
		world.setBlock(i + 3, j + 0, k + 2, ModBlocks.ShadowStone.blockID);
		world.setBlock(i + 3, j + 0, k + 3, ModBlocks.ShadowStone.blockID);
		world.setBlock(i + 3, j + 0, k + 4, ModBlocks.ShadowStone.blockID);
		world.setBlock(i + 3, j + 0, k + 5, ModBlocks.ShadowStone.blockID);
		world.setBlock(i + 3, j + 0, k + 6, ModBlocks.ShadowStone.blockID);
		world.setBlock(i + 3, j + 1, k + 0, ModBlocks.ShadowStone.blockID);
		world.setBlock(i + 3, j + 1, k + 1, 0);
		world.setBlock(i + 3, j + 1, k + 2, 0);
		world.setBlock(i + 3, j + 1, k + 3, 0);
		world.setBlock(i + 3, j + 1, k + 4, 0);
		world.setBlock(i + 3, j + 1, k + 5, 0);
		world.setBlock(i + 3, j + 1, k + 6, ModBlocks.ShadowStone.blockID);
		world.setBlock(i + 3, j + 2, k + 0, ModBlocks.ShadowStone.blockID);
		world.setBlock(i + 3, j + 2, k + 1, 0);
		world.setBlock(i + 3, j + 2, k + 2, 0);
		world.setBlock(i + 3, j + 2, k + 3, 0);
		world.setBlock(i + 3, j + 2, k + 4, 0);
		world.setBlock(i + 3, j + 2, k + 5, 0);
		world.setBlock(i + 3, j + 2, k + 6, ModBlocks.ShadowStone.blockID);
		world.setBlock(i + 3, j + 3, k + 0, ModBlocks.ShadowStone.blockID);
		world.setBlock(i + 3, j + 3, k + 1, 0);
		world.setBlock(i + 3, j + 3, k + 2, 0);
		world.setBlock(i + 3, j + 3, k + 3, 0);
		world.setBlock(i + 3, j + 3, k + 4, 0);
		world.setBlock(i + 3, j + 3, k + 5, 0);
		world.setBlock(i + 3, j + 3, k + 6, ModBlocks.ShadowStone.blockID);
		world.setBlock(i + 3, j + 4, k + 0, ModBlocks.ShadowStone.blockID);
		world.setBlock(i + 3, j + 4, k + 1, ModBlocks.ShadowStone.blockID);
		world.setBlock(i + 3, j + 4, k + 2, ModBlocks.ShadowStone.blockID);
		world.setBlock(i + 3, j + 4, k + 3, ModBlocks.ShadowStone.blockID);
		world.setBlock(i + 3, j + 4, k + 4, ModBlocks.ShadowStone.blockID);
		world.setBlock(i + 3, j + 4, k + 5, ModBlocks.ShadowStone.blockID);
		world.setBlock(i + 3, j + 4, k + 6, ModBlocks.ShadowStone.blockID);
		world.setBlock(i + 4, j + 0, k + 0, ModBlocks.ShadowStone.blockID);
		world.setBlock(i + 4, j + 0, k + 1, ModBlocks.ShadowStone.blockID);
		world.setBlock(i + 4, j + 0, k + 2, ModBlocks.ShadowStone.blockID);
		world.setBlock(i + 4, j + 0, k + 3, ModBlocks.ShadowStone.blockID);
		world.setBlock(i + 4, j + 0, k + 4, ModBlocks.ShadowStone.blockID);
		world.setBlock(i + 4, j + 0, k + 5, ModBlocks.ShadowStone.blockID);
		world.setBlock(i + 4, j + 0, k + 6, ModBlocks.ShadowStone.blockID);
		world.setBlock(i + 4, j + 1, k + 0, ModBlocks.ShadowStone.blockID);
		world.setBlock(i + 4, j + 1, k + 1, 0);
		world.setBlock(i + 4, j + 1, k + 2, 0);
		world.setBlock(i + 4, j + 1, k + 3, ModBlocks.EnderForge.blockID);
		world.setBlock(i + 4, j + 1, k + 4, 0);
		world.setBlock(i + 4, j + 1, k + 5, 0);
		world.setBlock(i + 4, j + 1, k + 6, ModBlocks.ShadowStone.blockID);
		world.setBlock(i + 4, j + 2, k + 0, ModBlocks.ShadowStone.blockID);
		world.setBlock(i + 4, j + 2, k + 1, 0);
		world.setBlock(i + 4, j + 2, k + 2, 0);
		world.setBlock(i + 4, j + 2, k + 3, 0);
		world.setBlock(i + 4, j + 2, k + 4, 0);
		world.setBlock(i + 4, j + 2, k + 5, 0);
		world.setBlock(i + 4, j + 2, k + 6, ModBlocks.ShadowStone.blockID);
		world.setBlock(i + 4, j + 3, k + 0, ModBlocks.ShadowStone.blockID);
		world.setBlock(i + 4, j + 3, k + 1, 0);
		world.setBlock(i + 4, j + 3, k + 2, 0);
		world.setBlock(i + 4, j + 3, k + 3, 0);
		world.setBlock(i + 4, j + 3, k + 4, 0);
		world.setBlock(i + 4, j + 3, k + 5, 0);
		world.setBlock(i + 4, j + 3, k + 6, ModBlocks.ShadowStone.blockID);
		world.setBlock(i + 4, j + 4, k + 0, ModBlocks.ShadowStone.blockID);
		world.setBlock(i + 4, j + 4, k + 1, ModBlocks.ShadowStone.blockID);
		world.setBlock(i + 4, j + 4, k + 2, ModBlocks.ShadowStone.blockID);
		world.setBlock(i + 4, j + 4, k + 3, ModBlocks.ShadowStone.blockID);
		world.setBlock(i + 4, j + 4, k + 4, ModBlocks.ShadowStone.blockID);
		world.setBlock(i + 4, j + 4, k + 5, ModBlocks.ShadowStone.blockID);
		world.setBlock(i + 4, j + 4, k + 6, ModBlocks.ShadowStone.blockID);
		world.setBlock(i + 5, j + 0, k + 0, ModBlocks.ShadowStone.blockID);
		world.setBlock(i + 5, j + 0, k + 1, ModBlocks.ShadowStone.blockID);
		world.setBlock(i + 5, j + 0, k + 2, ModBlocks.ShadowStone.blockID);
		world.setBlock(i + 5, j + 0, k + 3, ModBlocks.ShadowStone.blockID);
		world.setBlock(i + 5, j + 0, k + 4, ModBlocks.ShadowStone.blockID);
		world.setBlock(i + 5, j + 0, k + 5, ModBlocks.ShadowStone.blockID);
		world.setBlock(i + 5, j + 0, k + 6, ModBlocks.ShadowStone.blockID);
		world.setBlock(i + 5, j + 1, k + 0, ModBlocks.ShadowStone.blockID);
		world.setBlock(i + 5, j + 1, k + 1, 0);
		world.setBlock(i + 5, j + 1, k + 2, 0);
		world.setBlock(i + 5, j + 1, k + 3, 0);
		world.setBlock(i + 5, j + 1, k + 4, 0);
		world.setBlock(i + 5, j + 1, k + 5, 0);
		world.setBlock(i + 5, j + 1, k + 6, ModBlocks.ShadowStone.blockID);
		world.setBlock(i + 5, j + 2, k + 0, ModBlocks.ShadowStone.blockID);
		world.setBlock(i + 5, j + 2, k + 1, 0);
		world.setBlock(i + 5, j + 2, k + 2, 0);
		world.setBlock(i + 5, j + 2, k + 3, 0);
		world.setBlock(i + 5, j + 2, k + 4, 0);
		world.setBlock(i + 5, j + 2, k + 5, 0);
		world.setBlock(i + 5, j + 2, k + 6, ModBlocks.ShadowStone.blockID);
		world.setBlock(i + 5, j + 3, k + 0, ModBlocks.ShadowStone.blockID);
		world.setBlock(i + 5, j + 3, k + 1, 0);
		world.setBlock(i + 5, j + 3, k + 2, 0);
		world.setBlock(i + 5, j + 3, k + 3, 0);
		world.setBlock(i + 5, j + 3, k + 4, 0);
		world.setBlock(i + 5, j + 3, k + 5, 0);
		world.setBlock(i + 5, j + 3, k + 6, ModBlocks.ShadowStone.blockID);
		world.setBlock(i + 5, j + 4, k + 0, ModBlocks.ShadowStone.blockID);
		world.setBlock(i + 5, j + 4, k + 1, ModBlocks.ShadowStone.blockID);
		world.setBlock(i + 5, j + 4, k + 2, ModBlocks.ShadowStone.blockID);
		world.setBlock(i + 5, j + 4, k + 3, ModBlocks.ShadowStone.blockID);
		world.setBlock(i + 5, j + 4, k + 4, ModBlocks.ShadowStone.blockID);
		world.setBlock(i + 5, j + 4, k + 5, ModBlocks.ShadowStone.blockID);
		world.setBlock(i + 5, j + 4, k + 6, ModBlocks.ShadowStone.blockID);
		world.setBlock(i + 6, j + 0, k + 0, ModBlocks.ShadowStone.blockID);
		world.setBlock(i + 6, j + 0, k + 1, ModBlocks.ShadowStone.blockID);
		world.setBlock(i + 6, j + 0, k + 2, ModBlocks.ShadowStone.blockID);
		world.setBlock(i + 6, j + 0, k + 3, ModBlocks.ShadowStone.blockID);
		world.setBlock(i + 6, j + 0, k + 4, ModBlocks.ShadowStone.blockID);
		world.setBlock(i + 6, j + 0, k + 5, ModBlocks.ShadowStone.blockID);
		world.setBlock(i + 6, j + 0, k + 6, ModBlocks.ShadowStone.blockID);
		world.setBlock(i + 6, j + 1, k + 0, ModBlocks.ShadowStone.blockID);
		world.setBlock(i + 6, j + 1, k + 1, 0);
		world.setBlock(i + 6, j + 1, k + 2, 0);
		world.setBlock(i + 6, j + 1, k + 3, 0);
		world.setBlock(i + 6, j + 1, k + 4, 0);
		world.setBlock(i + 6, j + 1, k + 5, 0);
		world.setBlock(i + 6, j + 1, k + 6, ModBlocks.ShadowStone.blockID);
		world.setBlock(i + 6, j + 2, k + 0, ModBlocks.ShadowStone.blockID);
		world.setBlock(i + 6, j + 2, k + 1, 0);
		world.setBlock(i + 6, j + 2, k + 2, 0);
		world.setBlock(i + 6, j + 2, k + 3, 0);
		world.setBlock(i + 6, j + 2, k + 4, 0);
		world.setBlock(i + 6, j + 2, k + 5, 0);
		world.setBlock(i + 6, j + 2, k + 6, ModBlocks.ShadowStone.blockID);
		world.setBlock(i + 6, j + 3, k + 0, ModBlocks.ShadowStone.blockID);
		world.setBlock(i + 6, j + 3, k + 1, 0);
		world.setBlock(i + 6, j + 3, k + 2, 0);
		world.setBlock(i + 6, j + 3, k + 3, 0);
		world.setBlock(i + 6, j + 3, k + 4, 0);
		world.setBlock(i + 6, j + 3, k + 5, 0);
		world.setBlock(i + 6, j + 3, k + 6, ModBlocks.ShadowStone.blockID);
		world.setBlock(i + 6, j + 4, k + 0, ModBlocks.ShadowStone.blockID);
		world.setBlock(i + 6, j + 4, k + 1, ModBlocks.ShadowStone.blockID);
		world.setBlock(i + 6, j + 4, k + 2, ModBlocks.ShadowStone.blockID);
		world.setBlock(i + 6, j + 4, k + 3, ModBlocks.ShadowStone.blockID);
		world.setBlock(i + 6, j + 4, k + 4, ModBlocks.ShadowStone.blockID);
		world.setBlock(i + 6, j + 4, k + 5, ModBlocks.ShadowStone.blockID);
		world.setBlock(i + 6, j + 4, k + 6, ModBlocks.ShadowStone.blockID);
		world.setBlock(i + 7, j + 0, k + 0, ModBlocks.ShadowStone.blockID);
		world.setBlock(i + 7, j + 0, k + 1, ModBlocks.ShadowStone.blockID);
		world.setBlock(i + 7, j + 0, k + 2, ModBlocks.ShadowStone.blockID);
		world.setBlock(i + 7, j + 0, k + 3, ModBlocks.ShadowStone.blockID);
		world.setBlock(i + 7, j + 0, k + 4, ModBlocks.ShadowStone.blockID);
		world.setBlock(i + 7, j + 0, k + 5, ModBlocks.ShadowStone.blockID);
		world.setBlock(i + 7, j + 0, k + 6, ModBlocks.ShadowStone.blockID);
		world.setBlock(i + 7, j + 1, k + 0, ModBlocks.ShadowStone.blockID);
		world.setBlock(i + 7, j + 1, k + 1, 0);
		world.setBlock(i + 7, j + 1, k + 2, 0);
		world.setBlock(i + 7, j + 1, k + 3, 0);
		world.setBlock(i + 7, j + 1, k + 4, 0);
		world.setBlock(i + 7, j + 1, k + 5, 0);
		world.setBlock(i + 7, j + 1, k + 6, ModBlocks.ShadowStone.blockID);
		world.setBlock(i + 7, j + 2, k + 0, ModBlocks.ShadowStone.blockID);
		world.setBlock(i + 7, j + 2, k + 1, 0);
		world.setBlock(i + 7, j + 2, k + 2, 0);
		world.setBlock(i + 7, j + 2, k + 3, 0);
		world.setBlock(i + 7, j + 2, k + 4, 0);
		world.setBlock(i + 7, j + 2, k + 5, 0);
		world.setBlock(i + 7, j + 2, k + 6, ModBlocks.ShadowStone.blockID);
		world.setBlock(i + 7, j + 3, k + 0, ModBlocks.ShadowStone.blockID);
		world.setBlock(i + 7, j + 3, k + 1, 0);
		world.setBlock(i + 7, j + 3, k + 2, 0);
		world.setBlock(i + 7, j + 3, k + 3, 0);
		world.setBlock(i + 7, j + 3, k + 4, 0);
		world.setBlock(i + 7, j + 3, k + 5, 0);
		world.setBlock(i + 7, j + 3, k + 6, ModBlocks.ShadowStone.blockID);
		world.setBlock(i + 7, j + 4, k + 0, ModBlocks.ShadowStone.blockID);
		world.setBlock(i + 7, j + 4, k + 1, ModBlocks.ShadowStone.blockID);
		world.setBlock(i + 7, j + 4, k + 2, ModBlocks.ShadowStone.blockID);
		world.setBlock(i + 7, j + 4, k + 3, ModBlocks.ShadowStone.blockID);
		world.setBlock(i + 7, j + 4, k + 4, ModBlocks.ShadowStone.blockID);
		world.setBlock(i + 7, j + 4, k + 5, ModBlocks.ShadowStone.blockID);
		world.setBlock(i + 7, j + 4, k + 6, ModBlocks.ShadowStone.blockID);
		world.setBlock(i + 8, j + 0, k + 0, ModBlocks.ShadowStone.blockID);
		world.setBlock(i + 8, j + 0, k + 1, ModBlocks.ShadowStone.blockID);
		world.setBlock(i + 8, j + 0, k + 2, ModBlocks.ShadowStone.blockID);
		world.setBlock(i + 8, j + 0, k + 3, ModBlocks.ShadowStone.blockID);
		world.setBlock(i + 8, j + 0, k + 4, ModBlocks.ShadowStone.blockID);
		world.setBlock(i + 8, j + 0, k + 5, ModBlocks.ShadowStone.blockID);
		world.setBlock(i + 8, j + 0, k + 6, ModBlocks.ShadowStone.blockID);
		world.setBlock(i + 8, j + 1, k + 0, ModBlocks.ShadowStone.blockID);
		world.setBlock(i + 8, j + 1, k + 1, ModBlocks.ShadowStone.blockID);
		world.setBlock(i + 8, j + 1, k + 2, ModBlocks.ShadowStone.blockID);
		world.setBlock(i + 8, j + 1, k + 3, ModBlocks.ShadowStone.blockID);
		world.setBlock(i + 8, j + 1, k + 4, ModBlocks.ShadowStone.blockID);
		world.setBlock(i + 8, j + 1, k + 5, ModBlocks.ShadowStone.blockID);
		world.setBlock(i + 8, j + 1, k + 6, ModBlocks.ShadowStone.blockID);
		world.setBlock(i + 8, j + 2, k + 0, ModBlocks.ShadowStone.blockID);
		world.setBlock(i + 8, j + 2, k + 1, ModBlocks.ShadowStone.blockID);
		world.setBlock(i + 8, j + 2, k + 2, ModBlocks.ShadowStone.blockID);
		world.setBlock(i + 8, j + 2, k + 3, ModBlocks.ShadowStone.blockID);
		world.setBlock(i + 8, j + 2, k + 4, ModBlocks.ShadowStone.blockID);
		world.setBlock(i + 8, j + 2, k + 5, ModBlocks.ShadowStone.blockID);
		world.setBlock(i + 8, j + 2, k + 6, ModBlocks.ShadowStone.blockID);
		world.setBlock(i + 8, j + 3, k + 0, ModBlocks.ShadowStone.blockID);
		world.setBlock(i + 8, j + 3, k + 1, ModBlocks.ShadowStone.blockID);
		world.setBlock(i + 8, j + 3, k + 2, ModBlocks.ShadowStone.blockID);
		world.setBlock(i + 8, j + 3, k + 3, ModBlocks.ShadowStone.blockID);
		world.setBlock(i + 8, j + 3, k + 4, ModBlocks.ShadowStone.blockID);
		world.setBlock(i + 8, j + 3, k + 5, ModBlocks.ShadowStone.blockID);
		world.setBlock(i + 8, j + 3, k + 6, ModBlocks.ShadowStone.blockID);
		world.setBlock(i + 8, j + 4, k + 0, ModBlocks.ShadowStone.blockID);
		world.setBlock(i + 8, j + 4, k + 1, ModBlocks.ShadowStone.blockID);
		world.setBlock(i + 8, j + 4, k + 2, ModBlocks.ShadowStone.blockID);
		world.setBlock(i + 8, j + 4, k + 3, ModBlocks.ShadowStone.blockID);
		world.setBlock(i + 8, j + 4, k + 4, ModBlocks.ShadowStone.blockID);
		world.setBlock(i + 8, j + 4, k + 5, ModBlocks.ShadowStone.blockID);
		world.setBlock(i + 8, j + 4, k + 6, ModBlocks.ShadowStone.blockID);

		return true;
	}
}
